<robot name="dumpUrdf">
	<link name="base" >
		<inertial>
			<origin rpy = "0 0 0" xyz = "0 0 0" />
			<mass value = "0.0001" />
			<inertia ixx = "0.0001" ixy = "0" ixz = "0" iyy = "0.0001" iyz = "0" izz = "0.0001" />
		</inertial>
	</link>
	<!-- right_wrist -->
	<link name="right_wrist" >
		<inertial>
			<origin rpy = "0 0 0" xyz = "0 0 0.075" />
			<mass value = "0.500000" />
			<inertia ixx = "0.1" ixy = "0" ixz = "0" iyy = "0.1" iyz = "0" izz = "0.1" />
		</inertial>
		<collision>
			<origin rpy = "0 0 0" xyz = "0 0 0.075" />
			<geometry>
				<box size="0.15 0.04 0.15" />
			</geometry>
		</collision>
	</link>
	<joint name="right_wrist" type="fixed" >
		<parent link = "base" />
		<child link="right_wrist" />
        <origin rpy = "3.14 -1.57 1.57" xyz = "0 0 0" />
	</joint>
	<!-- thumb -->
	<link name="thumb_prox" >
		<inertial>
            <origin rpy = "0 0 0" xyz = "0 0 0.02" />
			<mass value = "0.05" />
			<inertia ixx = "0.1" ixy = "0" ixz = "0" iyy = "0.1" iyz = "0" izz = "0.1" />
		</inertial>
		<collision>
			<origin rpy = "0 0 0" xyz = "0 0 0.02" />
			<geometry>
				<box size="0.025 0.025 0.04" />
			</geometry>
		</collision>
	</link>
	<joint name="thumb_prox" type="revolute" >
		<parent link="right_wrist" />
		<child link="thumb_prox" />
		<origin rpy = "3.14 -2.81 0" xyz = "0.1 0 0" />
		<axis xyz = "0.000000 1.000000 0.000000" />
    	<limit effort="1000" lower="0" upper="2" velocity="0.5"/>
	</joint>
	<link name="thumb_inter" >
		<inertial>
            <origin rpy = "0 0 0" xyz = "0 0 0.02" />
			<mass value = "0.05" />
			<inertia ixx = "0.1" ixy = "0" ixz = "0" iyy = "0.1" iyz = "0" izz = "0.1" />
		</inertial>
		<collision>
			<origin rpy = "0 0 0" xyz = "0 0 0.02" />
			<geometry>
				<box size="0.025 0.025 0.04" />
			</geometry>
		</collision>
	</link>
	<joint name="thumb_inter" type="revolute" >
		<parent link="thumb_prox" />
		<child link="thumb_inter" />
		<limit effort="1000.0" lower="0" upper="2" velocity="0.5"/>
		<origin rpy = "0 0 0" xyz = "0 0 0.056" />
		<axis xyz = "0.000000 1.000000 0.000000" />
	</joint>
	<link name="thumb_dist" >
		<inertial>
            <origin rpy = "0 0 0" xyz = "0 0 0.02" />
			<mass value = "0.05" />
			<inertia ixx = "0.1" ixy = "0" ixz = "0" iyy = "0.1" iyz = "0" izz = "0.1" />
		</inertial>
		<collision>
			<origin rpy = "0 0 0" xyz = "0 0 0.02" />
			<geometry>
				<box size="0.025 0.025 0.04" />
			</geometry>
		</collision>
	</link>
	<joint name="thumb_dist" type="revolute" >
		<parent link="thumb_inter" />
		<child link="thumb_dist" />
		<limit effort="1000.0" lower="0" upper="2" velocity="0.5"/>
		<origin rpy = "0 0 0" xyz = "0 0 0.066" />
		<axis xyz = "0.000000 1.000000 0.000000" />
	</joint>
	<!-- index -->
	<link name="index_prox" >
		<inertial>
            <origin rpy = "0 0 0" xyz = "0 0 0.02" />
			<mass value = "0.05" />
			<inertia ixx = "0.1" ixy = "0" ixz = "0" iyy = "0.1" iyz = "0" izz = "0.1" />
		</inertial>
		<collision>
			<origin rpy = "0 0 0" xyz = "0 0 0.02" />
			<geometry>
				<box size="0.025 0.025 0.04" />
			</geometry>
		</collision>
	</link>
	<joint name="index_prox" type="revolute" >
		<parent link="right_wrist" />
		<child link="index_prox" />
		<origin rpy = "0 0 0" xyz = "0.08 0 0.22" />
		<axis xyz = "1.000000 0.000000 0.000000" />
    	<limit effort="1000" lower="0" upper="2" velocity="0.5"/>
	</joint>
	<link name="index_inter" >
		<inertial>
            <origin rpy = "0 0 0" xyz = "0 0 0.02" />
			<mass value = "0.05" />
			<inertia ixx = "0.1" ixy = "0" ixz = "0" iyy = "0.1" iyz = "0" izz = "0.1" />
		</inertial>
		<collision>
			<origin rpy = "0 0 0" xyz = "0 0 0.02" />
			<geometry>
				<box size="0.025 0.025 0.04" />
			</geometry>
		</collision>
	</link>
	<joint name="index_inter" type="revolute" >
		<parent link="index_prox" />
		<child link="index_inter" />
		<limit effort="1000.0" lower="0" upper="2" velocity="0.5"/>
		<origin rpy = "0 0 0" xyz = "0 0 0.061" />
		<axis xyz = "1.000000 0.000000 0.000000" />
	</joint>
	<link name="index_dist" >
		<inertial>
            <origin rpy = "0 0 0" xyz = "0 0 0.02" />
			<mass value = "0.05" />
			<inertia ixx = "0.1" ixy = "0" ixz = "0" iyy = "0.1" iyz = "0" izz = "0.1" />
		</inertial>
		<collision>
			<origin rpy = "0 0 0" xyz = "0 0 0.02" />
			<geometry>
				<box size="0.025 0.025 0.04" />
			</geometry>
		</collision>
	</link>
	<joint name="index_dist" type="revolute" >
		<parent link="index_inter" />
		<child link="index_dist" />
		<limit effort="1000.0" lower="0" upper="2" velocity="0.5"/>
		<origin rpy = "0 0 0" xyz = "0 0 0.061" />
		<axis xyz = "1.000000 0.000000 0.000000" />
	</joint>
	<!-- middle -->
	<link name="middle_prox" >
		<inertial>
            <origin rpy = "0 0 0" xyz = "0 0 0.02" />
			<mass value = "0.05" />
			<inertia ixx = "0.1" ixy = "0" ixz = "0" iyy = "0.1" iyz = "0" izz = "0.1" />
		</inertial>
		<collision>
			<origin rpy = "0 0 0" xyz = "0 0 0.02" />
			<geometry>
				<box size="0.025 0.025 0.04" />
			</geometry>
		</collision>
	</link>
	<joint name="middle_prox" type="revolute" >
		<parent link="right_wrist" />
		<child link="middle_prox" />
		<origin rpy = "0 0 0.1" xyz = "0.01 0 0.227" />
		<axis xyz = "1.000000 0.000000 0.000000" />
    	<limit effort="1000" lower="0" upper="2" velocity="0.5"/>
	</joint>
	<link name="middle_inter" >
		<inertial>
            <origin rpy = "0 0 0" xyz = "0 0 0.02" />
			<mass value = "0.05" />
			<inertia ixx = "0.1" ixy = "0" ixz = "0" iyy = "0.1" iyz = "0" izz = "0.1" />
		</inertial>
		<collision>
			<origin rpy = "0 0 0" xyz = "0 0 0.02" />
			<geometry>
				<box size="0.025 0.025 0.04" />
			</geometry>
		</collision>
	</link>
	<joint name="middle_inter" type="revolute" >
		<parent link="middle_prox" />
		<child link="middle_inter" />
		<limit effort="1000.0" lower="0" upper="2" velocity="0.5"/>
		<origin rpy = "0 0 0" xyz = "0 0 0.060" />
		<axis xyz = "1.000000 0.000000 0.000000" />
	</joint>
	<link name="middle_dist" >
		<inertial>
            <origin rpy = "0 0 0" xyz = "0 0 0.02" />
			<mass value = "0.05" />
			<inertia ixx = "0.1" ixy = "0" ixz = "0" iyy = "0.1" iyz = "0" izz = "0.1" />
		</inertial>
		<collision>
			<origin rpy = "0 0 0" xyz = "0 0 0.02" />
			<geometry>
				<box size="0.025 0.025 0.04" />
			</geometry>
		</collision>
	</link>
	<joint name="middle_dist" type="revolute" >
		<parent link="middle_inter" />
		<child link="middle_dist" />
		<limit effort="1000.0" lower="0" upper="2" velocity="0.5"/>
		<origin rpy = "0 0 0" xyz = "0 0 0.062" />
		<axis xyz = "1.000000 0.000000 0.000000" />
	</joint>
	<!-- ring -->
	<link name="ring_prox" >
		<inertial>
            <origin rpy = "0 0 0" xyz = "0 0 0.02" />
			<mass value = "0.05" />
			<inertia ixx = "0.1" ixy = "0" ixz = "0" iyy = "0.1" iyz = "0" izz = "0.1" />
		</inertial>
		<collision>
			<origin rpy = "0 0 0" xyz = "0 0 0.02" />
			<geometry>
				<box size="0.025 0.025 0.04" />
			</geometry>
		</collision>
	</link>
	<joint name="ring_prox" type="revolute" >
		<parent link="right_wrist" />
		<child link="ring_prox" />
		<origin rpy = "0 -0.05 0.11" xyz = "-0.057 0 0.189" />
		<axis xyz = "1.000000 0.000000 0.000000" />
    	<limit effort="1000" lower="0" upper="2" velocity="0.5"/>
	</joint>
	<link name="ring_inter" >
		<inertial>
            <origin rpy = "0 0 0" xyz = "0 0 0.02" />
			<mass value = "0.05" />
			<inertia ixx = "0.1" ixy = "0" ixz = "0" iyy = "0.1" iyz = "0" izz = "0.1" />
		</inertial>
		<collision>
			<origin rpy = "0 0 0" xyz = "0 0 0.02" />
			<geometry>
				<box size="0.025 0.025 0.04" />
			</geometry>
		</collision>
	</link>
	<joint name="ring_inter" type="revolute" >
		<parent link="ring_prox" />
		<child link="ring_inter" />
		<limit effort="1000.0" lower="0" upper="2" velocity="0.5"/>
		<origin rpy = "0 0 0" xyz = "0 0 0.059" />
		<axis xyz = "1.000000 0.000000 0.000000" />
	</joint>
	<link name="ring_dist" >
		<inertial>
            <origin rpy = "0 0 0" xyz = "0 0 0.02" />
			<mass value = "0.05" />
			<inertia ixx = "0.1" ixy = "0" ixz = "0" iyy = "0.1" iyz = "0" izz = "0.1" />
		</inertial>
		<collision>
			<origin rpy = "0 0 0" xyz = "0 0 0.02" />
			<geometry>
				<box size="0.025 0.025 0.04" />
			</geometry>
		</collision>
	</link>
	<joint name="ring_dist" type="revolute" >
		<parent link="ring_inter" />
		<child link="ring_dist" />
		<limit effort="1000.0" lower="0" upper="2" velocity="0.5"/>
		<origin rpy = "0 0 0" xyz = "0 0 0.052" />
		<axis xyz = "1.000000 0.000000 0.000000" />
	</joint>
	<!-- pinkie -->
	<link name="pinkie_prox" >
		<inertial>
            <origin rpy = "0 0 0" xyz = "0 0 0.02" />
			<mass value = "0.05" />
			<inertia ixx = "0.1" ixy = "0" ixz = "0" iyy = "0.1" iyz = "0" izz = "0.1" />
		</inertial>
		<collision>
			<origin rpy = "0 0 0" xyz = "0 0 0.02" />
			<geometry>
				<box size="0.025 0.025 0.04" />
			</geometry>
		</collision>
	</link>
	<joint name="pinkie_prox" type="revolute" >
		<parent link="right_wrist" />
		<child link="pinkie_prox" />
		<origin rpy = "0 -0.13 0.21" xyz = "-0.108 0 0.123" />
		<axis xyz = "1.000000 0.000000 0.000000" />
    	<limit effort="1000" lower="0" upper="2" velocity="0.5"/>
	</joint>
	<link name="pinkie_inter" >
		<inertial>
            <origin rpy = "0 0 0" xyz = "0 0 0.02" />
			<mass value = "0.05" />
			<inertia ixx = "0.1" ixy = "0" ixz = "0" iyy = "0.1" iyz = "0" izz = "0.1" />
		</inertial>
		<collision>
			<origin rpy = "0 0 0" xyz = "0 0 0.02" />
			<geometry>
				<box size="0.025 0.025 0.04" />
			</geometry>
		</collision>
	</link>
	<joint name="pinkie_inter" type="revolute" >
		<parent link="pinkie_prox" />
		<child link="pinkie_inter" />
		<limit effort="1000.0" lower="0" upper="2" velocity="0.5"/>
		<origin rpy = "0 0 0" xyz = "0 0 0.045" />
		<axis xyz = "1.000000 0.000000 0.000000" />
	</joint>
	<link name="pinkie_dist" >
		<inertial>
            <origin rpy = "0 0 0" xyz = "0 0 0.02" />
			<mass value = "0.05" />
			<inertia ixx = "0.1" ixy = "0" ixz = "0" iyy = "0.1" iyz = "0" izz = "0.1" />
		</inertial>
		<collision>
			<origin rpy = "0 0 0" xyz = "0 0 0.02" />
			<geometry>
				<box size="0.025 0.025 0.04" />
			</geometry>
		</collision>
	</link>
	<joint name="pinkie_dist" type="revolute" >
		<parent link="pinkie_inter" />
		<child link="pinkie_dist" />
		<limit effort="1000.0" lower="0" upper="2" velocity="0.5"/>
		<origin rpy = "0 0 0" xyz = "0 0 0.044" />
		<axis xyz = "1.000000 0.000000 0.000000" />
	</joint>
</robot>
