<robot name="dumpUrdf">
	<link name="base" >
		<inertial>
			<origin rpy = "0 0 0" xyz = "0 0 0" />
			<mass value = "0.0001" />
			<inertia ixx = "0.0001" ixy = "0" ixz = "0" iyy = "0.0001" iyz = "0" izz = "0.0001" />
		</inertial>
	</link>
	<link name="palm" >
		<inertial>
            <origin rpy = "0 0 0" xyz = "0.000000 -0.360000 0.000000" />
			<mass value = "0.45" />
			<inertia ixx = "0.1" ixy = "0" ixz = "0" iyy = "0.1" iyz = "0" izz = "0.1" />
		</inertial>
		<collision>
            <origin rpy = "0 0 0" xyz = "0.000000 -0.360000 0.000000" />
			<geometry>
				<box size="0.6 0.6 0.2" />
			</geometry>
		</collision>
	</link>
	<joint name="palm" type="fixed" >
		<parent link = "base" />
		<child link="palm" />
        <origin rpy = "0 0 0" xyz = "0.000000 0.000000 0.000000" />
	</joint>
	<!-- thumb -->
	<link name="thumb_prox" >
		<inertial>
            <origin rpy = "0 1.57 0" xyz = "0.12 0.0000 0.000000" />
			<mass value = "0.05" />
			<inertia ixx = "0.1" ixy = "0" ixz = "0" iyy = "0.1" iyz = "0" izz = "0.1" />
		</inertial>
		<collision>
			<origin rpy = "0 1.57 0" xyz = "0.12 0.000 0.000000" />
			<geometry>
				<capsule length="0.120" radius="0.06" />
			</geometry>
		</collision>
	</link>
	<joint name="thumb_prox" type="spherical" >
		<parent link="palm" />
		<child link="thumb_prox" />
		<origin rpy = "0 0 0" xyz = "0.3000 -0.360 0.0" />
	</joint>
	<link name="thumb_inter" >
		<inertial>
			<origin rpy = "0 1.57 0" xyz = "0.12000 0.0000 0.000000" />
			<mass value = "0.05" />
			<inertia ixx = "0.1" ixy = "0" ixz = "0" iyy = "0.1" iyz = "0" izz = "0.1" />
		</inertial>
		<collision>
			<origin rpy = "0 1.57 0" xyz = "0.12000 0.00 0.000000" />
			<geometry>
				<capsule length="0.12" radius="0.06"/>
			</geometry>
		</collision>
	</link>
	<joint name="thumb_inter" type="revolute" >
		<parent link="thumb_prox" />
		<child link="thumb_inter" />
		<limit effort="1000.0" lower="0" upper="3.14" velocity="0.5"/>
		<origin rpy = "0 0 0" xyz = "0.2400 0.00 0.000000" />
		<axis xyz = "0.000000 1.000000 0.000000" />
	</joint>
	<!-- index -->
	<link name="index_prox" >
		<inertial>
            <origin rpy = "1.57 0 0" xyz = "0.00000 -0.120000 0.000000" />
			<mass value = "0.05" />
			<inertia ixx = "0.1" ixy = "0" ixz = "0" iyy = "0.1" iyz = "0" izz = "0.1" />
		</inertial>
		<collision>
			<origin rpy = "1.57 0 0" xyz = "0.00000 -0.12000 0.000000" />
			<geometry>
				<capsule length="0.120" radius="0.06" />
			</geometry>
		</collision>
	</link>
	<joint name="index_prox" type="spherical" >
		<parent link="palm" />
		<child link="index_prox" />
		<origin rpy = "0 0 0" xyz = "0.2000 -0.66000 0.0" />
	</joint>
	<link name="index_inter" >
		<inertial>
			<origin rpy = "1.57 0 0" xyz = "0.00000 -0.120000 0.000000" />
			<mass value = "0.05" />
			<inertia ixx = "0.1" ixy = "0" ixz = "0" iyy = "0.1" iyz = "0" izz = "0.1" />
		</inertial>
		<collision>
			<origin rpy = "1.57 0 0" xyz = "0.00000 -0.1200 0.000000" />
			<geometry>
				<capsule length="0.12" radius="0.06"/>
			</geometry>
		</collision>
	</link>
	<joint name="index_inter" type="revolute" >
		<parent link="index_prox" />
		<child link="index_inter" />
		<limit effort="1000.0" lower="0" upper="3.14" velocity="0.5"/>
		<origin rpy = "0 0 0" xyz = "0.000000 -0.2400 0.000000" />
		<axis xyz = "0.000000 1.000000 0.000000" />
	</joint>
	<link name="index_dist" >
		<inertial>
			<origin rpy = "1.57 0 0" xyz = "0.00000 -0.120000 0.000000" />
			<mass value = "0.05" />
			<inertia ixx = "0.1" ixy = "0" ixz = "0" iyy = "0.1" iyz = "0" izz = "0.1" />
		</inertial>
		<collision>
			<origin rpy = "1.57 0 0" xyz = "0.00000 -0.1200 0.000000" />
			<geometry>
				<capsule length="0.12" radius="0.06"/>
			</geometry>
		</collision>
	</link>
	<joint name="index_dist" type="revolute" >
		<parent link="index_inter" />
		<child link="index_dist" />
		<limit effort="1000.0" lower="0" upper="3.14" velocity="0.5"/>
		<origin rpy = "0 0 0" xyz = "0.000000 -0.2400 0.000000" />
		<axis xyz = "0.000000 1.000000 0.000000" />
	</joint>
	<!-- middle -->
	<link name="middle_prox" >
		<inertial>
            <origin rpy = "1.57 0 0" xyz = "0.00000 -0.120000 0.000000" />
			<mass value = "0.05" />
			<inertia ixx = "0.1" ixy = "0" ixz = "0" iyy = "0.1" iyz = "0" izz = "0.1" />
		</inertial>
		<collision>
			<origin rpy = "1.57 0 0" xyz = "0.00000 -0.12000 0.000000" />
			<geometry>
				<capsule length="0.120" radius="0.06" />
			</geometry>
		</collision>
	</link>
	<joint name="middle_prox" type="spherical" >
		<parent link="palm" />
		<child link="middle_prox" />
		<origin rpy = "0 0 0" xyz = "0.08000 -0.66000 0.0" />
	</joint>
	<link name="middle_inter" >
		<inertial>
			<origin rpy = "1.57 0 0" xyz = "0.00000 -0.240000 0.000000" />
			<mass value = "0.05" />
			<inertia ixx = "0.1" ixy = "0" ixz = "0" iyy = "0.1" iyz = "0" izz = "0.1" />
		</inertial>
		<collision>
			<origin rpy = "1.57 0 0" xyz = "0.00000 -0.1200 0.000000" />
			<geometry>
				<capsule length="0.12" radius="0.06"/>
			</geometry>
		</collision>
	</link>
	<joint name="middle_inter" type="revolute" >
		<parent link="middle_prox" />
		<child link="middle_inter" />
		<limit effort="1000.0" lower="0" upper="3.14" velocity="0.5"/>
		<origin rpy = "0 0 0" xyz = "0.000000 -0.2400 0.000000" />
		<axis xyz = "0.000000 1.000000 0.000000" />
	</joint>
	<link name="middle_dist" >
		<inertial>
			<origin rpy = "1.57 0 0" xyz = "0.00000 -0.240000 0.000000" />
			<mass value = "0.05" />
			<inertia ixx = "0.1" ixy = "0" ixz = "0" iyy = "0.1" iyz = "0" izz = "0.1" />
		</inertial>
		<collision>
			<origin rpy = "1.57 0 0" xyz = "0.00000 -0.1200 0.000000" />
			<geometry>
				<capsule length="0.12" radius="0.06"/>
			</geometry>
		</collision>
	</link>
	<joint name="middle_dist" type="revolute" >
		<parent link="middle_inter" />
		<child link="middle_dist" />
		<limit effort="1000.0" lower="0" upper="3.14" velocity="0.5"/>
		<origin rpy = "0 0 0" xyz = "0.000000 -0.2400 0.000000" />
		<axis xyz = "0.000000 1.000000 0.000000" />
	</joint>
	<!-- ring -->
	<link name="ring_prox" >
		<inertial>
            <origin rpy = "1.57 0 0" xyz = "0.00000 -0.120000 0.000000" />
			<mass value = "0.05" />
			<inertia ixx = "0.1" ixy = "0" ixz = "0" iyy = "0.1" iyz = "0" izz = "0.1" />
		</inertial>
		<collision>
			<origin rpy = "1.57 0 0" xyz = "0.00000 -0.12000 0.000000" />
			<geometry>
				<capsule length="0.120" radius="0.06" />
			</geometry>
		</collision>
	</link>
	<joint name="ring_prox" type="spherical" >
		<parent link="palm" />
		<child link="ring_prox" />
		<origin rpy = "0 0 0" xyz = "-0.04000 -0.66000 0.0" />
	</joint>
	<link name="ring_inter" >
		<inertial>
			<origin rpy = "1.57 0 0" xyz = "0.00000 -0.240000 0.000000" />
			<mass value = "0.05" />
			<inertia ixx = "0.1" ixy = "0" ixz = "0" iyy = "0.1" iyz = "0" izz = "0.1" />
		</inertial>
		<collision>
			<origin rpy = "1.57 0 0" xyz = "0.00000 -0.1200 0.000000" />
			<geometry>
				<capsule length="0.12" radius="0.06"/>
			</geometry>
		</collision>
	</link>
	<joint name="ring_inter" type="revolute" >
		<parent link="ring_prox" />
		<child link="ring_inter" />
		<limit effort="1000.0" lower="0" upper="3.14" velocity="0.5"/>
		<origin rpy = "0 0 0" xyz = "0.000000 -0.2400 0.000000" />
		<axis xyz = "0.000000 1.000000 0.000000" />
	</joint>
	<link name="ring_dist" >
		<inertial>
			<origin rpy = "1.57 0 0" xyz = "0.00000 -0.240000 0.000000" />
			<mass value = "0.05" />
			<inertia ixx = "0.1" ixy = "0" ixz = "0" iyy = "0.1" iyz = "0" izz = "0.1" />
		</inertial>
		<collision>
			<origin rpy = "1.57 0 0" xyz = "0.00000 -0.1200 0.000000" />
			<geometry>
				<capsule length="0.12" radius="0.06"/>
			</geometry>
		</collision>
	</link>
	<joint name="ring_dist" type="revolute" >
		<parent link="ring_inter" />
		<child link="ring_dist" />
		<limit effort="1000.0" lower="0" upper="3.14" velocity="0.5"/>
		<origin rpy = "0 0 0" xyz = "0.000000 -0.2400 0.000000" />
		<axis xyz = "0.000000 1.000000 0.000000" />
	</joint>
	<!-- pinkie -->
	<link name="pinkie_prox" >
		<inertial>
            <origin rpy = "1.57 0 0" xyz = "0.00000 -0.120000 0.000000" />
			<mass value = "0.05" />
			<inertia ixx = "0.1" ixy = "0" ixz = "0" iyy = "0.1" iyz = "0" izz = "0.1" />
		</inertial>
		<collision>
			<origin rpy = "1.57 0 0" xyz = "0.00000 -0.12000 0.000000" />
			<geometry>
				<capsule length="0.120" radius="0.06" />
			</geometry>
		</collision>
	</link>
	<joint name="pinkie_prox" type="spherical" >
		<parent link="palm" />
		<child link="pinkie_prox" />
		<origin rpy = "0 0 0" xyz = "-0.1600 -0.66000 0.0" />
	</joint>
	<link name="pinkie_inter" >
		<inertial>
			<origin rpy = "1.57 0 0" xyz = "0.00000 -0.240000 0.000000" />
			<mass value = "0.05" />
			<inertia ixx = "0.1" ixy = "0" ixz = "0" iyy = "0.1" iyz = "0" izz = "0.1" />
		</inertial>
		<collision>
			<origin rpy = "1.57 0 0" xyz = "0.00000 -0.1200 0.000000" />
			<geometry>
				<capsule length="0.12" radius="0.06"/>
			</geometry>
		</collision>
	</link>
	<joint name="pinkie_inter" type="revolute" >
		<parent link="pinkie_prox" />
		<child link="pinkie_inter" />
		<limit effort="1000.0" lower="0" upper="3.14" velocity="0.5"/>
		<origin rpy = "0 0 0" xyz = "0.000000 -0.2400 0.000000" />
		<axis xyz = "0.000000 1.000000 0.000000" />
	</joint>
	<link name="pinkie_dist" >
		<inertial>
			<origin rpy = "1.57 0 0" xyz = "0.00000 -0.240000 0.000000" />
			<mass value = "0.05" />
			<inertia ixx = "0.1" ixy = "0" ixz = "0" iyy = "0.1" iyz = "0" izz = "0.1" />
		</inertial>
		<collision>
			<origin rpy = "1.57 0 0" xyz = "0.00000 -0.1200 0.000000" />
			<geometry>
				<capsule length="0.12" radius="0.06"/>
			</geometry>
		</collision>
	</link>
	<joint name="pinkie_dist" type="revolute" >
		<parent link="pinkie_inter" />
		<child link="pinkie_dist" />
		<limit effort="1000.0" lower="0" upper="3.14" velocity="0.5"/>
		<origin rpy = "0 0 0" xyz = "0.000000 -0.2400 0.000000" />
		<axis xyz = "0.000000 1.000000 0.000000" />
	</joint>
</robot>
