<robot name="dumpUrdf">
	<link name="base" >
		<inertial>
			<origin rpy = "0 0 0" xyz = "0 0 0" />
			<mass value = "0.0001" />
			<inertia ixx = "0.0001" ixy = "0" ixz = "0" iyy = "0.0001" iyz = "0" izz = "0.0001" />
		</inertial>
	</link>
	<link name="palm" >
		<inertial>
            <origin rpy = "0 0 0" xyz = "0.000000 -0.360000 0.000000" />
			<mass value = "6.000000" />
			<inertia ixx = "0.1" ixy = "0" ixz = "0" iyy = "0.1" iyz = "0" izz = "0.1" />
		</inertial>
		<collision>
            <origin rpy = "0 0 0" xyz = "0.000000 -0.360000 0.000000" />
			<geometry>
				<sphere radius = "0.360000" />
			</geometry>
		</collision>
	</link>
	<joint name="palm" type="fixed" >
		<parent link = "base" />
		<child link="palm" />
        <origin rpy = "-1.57 0 0" xyz = "0.000000 0.000000 0.000000" />
	</joint>
	<!-- THUMB -->
	<link name="thumb_prox" >
		<inertial>
            <origin rpy = "0 0 0" xyz = "0.00000 -0.510000 0.000000" />
			<mass value = "4.500000" />
			<inertia ixx = "0.1" ixy = "0" ixz = "0" iyy = "0.1" iyz = "0" izz = "0.1" />
		</inertial>
		<collision>
			<origin rpy = "-1.570796 0 0" xyz = "0.00000 -0.51000 0.000000" />
			<geometry>
				<capsule length="0.120" radius="0.06" />
			</geometry>
		</collision>
	</link>
	<joint name="thumb_prox" type="spherical" >
		<parent link="palm" />
		<child link="thumb_prox" />
		<origin rpy = "0 1.57 1.57" xyz = "0.00000 -0.42000 0.0" />
	</joint>
	<link name="thumb_inter" >
		<inertial>
			<origin rpy = "0 0 0" xyz = "0.00000 -0.810000 0.000000" />
			<mass value = "3.000000" />
			<inertia ixx = "0.1" ixy = "0" ixz = "0" iyy = "0.1" iyz = "0" izz = "0.1" />
		</inertial>
		<collision>
			<origin rpy = "-1.570796 0 0" xyz = "0.00000 -0.810000 0.000000" />
			<geometry>
				<capsule length="0.12" radius="0.06"/>
			</geometry>
		</collision>
	</link>
	<joint name="thumb_inter" type="revolute" >
		<parent link="thumb_prox" />
		<child link="thumb_inter" />
		<limit effort="1000.0" lower="-3.14" upper="0." velocity="0.5"/>
		<origin rpy = "0 0 0" xyz = "0.000000 0.00 0.000000" />
		<axis xyz = "0.000000 0.000000 1.000000" />
	</joint>
	<!-- INDEX -->
	<link name="index_prox" >
		<inertial>
            <origin rpy = "0 0 0" xyz = "0.0800000 -0.510000 0.000000" />
			<mass value = "4.500000" />
			<inertia ixx = "0.1" ixy = "0" ixz = "0" iyy = "0.1" iyz = "0" izz = "0.1" />
		</inertial>
		<collision>
			<origin rpy = "-1.570796 0 0" xyz = "0.0800000 -0.51000 0.000000" />
			<geometry>
				<capsule length="0.120" radius="0.06" />
			</geometry>
		</collision>
	</link>
	<joint name="index_prox" type="spherical" >
		<parent link="palm" />
		<child link="index_prox" />
		<origin rpy = "0 0 0" xyz = "0.0800000 -0.36000 0.0" />
	</joint>
	<link name="index_inter" >
		<inertial>
			<origin rpy = "0 0 0" xyz = "0.0800000 -0.810000 0.000000" />
			<mass value = "3.000000" />
			<inertia ixx = "0.1" ixy = "0" ixz = "0" iyy = "0.1" iyz = "0" izz = "0.1" />
		</inertial>
		<collision>
			<origin rpy = "-1.570796 0 0" xyz = "0.0800000 -0.810000 0.000000" />
			<geometry>
				<capsule length="0.12" radius="0.06"/>
			</geometry>
		</collision>
	</link>
	<joint name="index_inter" type="revolute" >
		<parent link="index_prox" />
		<child link="index_inter" />
		<limit effort="1000.0" lower="0" upper="3.14" velocity="0.5"/>
		<origin rpy = "0 0 0" xyz = "0.00000 0.00 0.000000" />
		<axis xyz = "0.000000 0.000000 1.000000" />
	</joint>
	<link name="index_dist" >
		<inertial>
			<origin rpy = "0 0 0" xyz = "0.0800000 -1.110000 0.000000" />
			<mass value = "3.000000" />
			<inertia ixx = "0.1" ixy = "0" ixz = "0" iyy = "0.1" iyz = "0" izz = "0.1" />
		</inertial>
		<collision>
			<origin rpy = "-1.570796 0 0" xyz = "0.0800000 -1.110000 0.000000" />
			<geometry>
				<capsule length="0.12" radius="0.06"/>
			</geometry>
		</collision>
	</link>
	<joint name="index_dist" type="revolute" >
		<parent link="index_inter" />
		<child link="index_dist" />
		<limit effort="1000.0" lower="-3.14" upper="0." velocity="0.5"/>
		<origin rpy = "0 0 0" xyz = "0.00000 0.00 0.000000" />
		<axis xyz = "0.000000 0.000000 1.000000" />
	</joint>
	<!-- MIDDLE -->
	<link name="middle_prox" >
		<inertial>
            <origin rpy = "0 0 0" xyz = "0.00000 -0.510000 0.000000" />
			<mass value = "4.500000" />
			<inertia ixx = "0.1" ixy = "0" ixz = "0" iyy = "0.1" iyz = "0" izz = "0.1" />
		</inertial>
		<collision>
			<origin rpy = "-1.570796 0 0" xyz = "0.00000 -0.51000 0.000000" />
			<geometry>
				<capsule length="0.120" radius="0.060000" />
			</geometry>
		</collision>
	</link>
	<joint name="middle_prox" type="spherical" >
		<parent link="palm" />
		<child link="middle_prox" />
		<origin rpy = "0 0 0" xyz = "0.00000 -0.36000 0.0" />
	</joint>
	<link name="middle_inter" >
		<inertial>
			<origin rpy = "0 0 0" xyz = "0.00000 -0.810000 0.000000" />
			<mass value = "3.000000" />
			<inertia ixx = "0.1" ixy = "0" ixz = "0" iyy = "0.1" iyz = "0" izz = "0.1" />
		</inertial>
		<collision>
			<origin rpy = "-1.570796 0 0" xyz = "0.00000 -0.810000 0.000000" />
			<geometry>
				<capsule length="0.12" radius="0.06"/>
			</geometry>
		</collision>
	</link>
	<joint name="middle_inter" type="revolute" >
		<parent link="middle_prox" />
		<child link="middle_inter" />
		<limit effort="1000.0" lower="-3.14" upper="0." velocity="0.5"/>
		<origin rpy = "0 0 0" xyz = "0.000000 0.00 0.000000" />
		<axis xyz = "0.000000 0.000000 1.000000" />
	</joint>
	<link name="middle_dist" >
		<inertial>
			<origin rpy = "0 0 0" xyz = "0.00000 -1.110000 0.000000" />
			<mass value = "3.000000" />
			<inertia ixx = "0.1" ixy = "0" ixz = "0" iyy = "0.1" iyz = "0" izz = "0.1" />
		</inertial>
		<collision>
			<origin rpy = "-1.570796 0 0" xyz = "0.00000 -1.110000 0.000000" />
			<geometry>
				<capsule length="0.12" radius="0.06"/>
			</geometry>
		</collision>
	</link>
	<joint name="middle_dist" type="revolute" >
		<parent link="middle_inter" />
		<child link="middle_dist" />
		<limit effort="1000.0" lower="-3.14" upper="0." velocity="0.5"/>
		<origin rpy = "0 0 0" xyz = "0.000000 0.00 0.000000" />
		<axis xyz = "0.000000 0.000000 1.000000" />
	</joint>
	<!-- RING -->
	<link name="ring_prox" >
		<inertial>
            <origin rpy = "0 0 0" xyz = "-0.080000 -0.510000 0.000000" />
			<mass value = "4.500000" />
			<inertia ixx = "0.1" ixy = "0" ixz = "0" iyy = "0.1" iyz = "0" izz = "0.1" />
		</inertial>
		<collision>
			<origin rpy = "-1.570796 0 0" xyz = "-0.080000 -0.51000 0.000000" />
			<geometry>
				<capsule length="0.120" radius="0.06" />
			</geometry>
		</collision>
	</link>
	<joint name="ring_prox" type="spherical" >
		<parent link="palm" />
		<child link="ring_prox" />
		<origin rpy = "0 0 0" xyz = "-0.080000 -0.36000 0.0" />
	</joint>
	<link name="ring_inter" >
		<inertial>
			<origin rpy = "0 0 0" xyz = "-0.080000 -0.810000 0.000000" />
			<mass value = "3.000000" />
			<inertia ixx = "0.1" ixy = "0" ixz = "0" iyy = "0.1" iyz = "0" izz = "0.1" />
		</inertial>
		<collision>
			<origin rpy = "-1.570796 0 0" xyz = "-0.080000 -0.810000 0.000000" />
			<geometry>
				<capsule length="0.12" radius="0.06"/>
			</geometry>
		</collision>
	</link>
	<joint name="ring_inter" type="revolute" >
		<parent link="ring_prox" />
		<child link="ring_inter" />
		<limit effort="1000.0" lower="-3.14" upper="0." velocity="0.5"/>
		<origin rpy = "0 0 0" xyz = "0.000000 0.00 0.000000" />
		<axis xyz = "0.000000 0.000000 1.000000" />
	</joint>
	<link name="ring_dist" >
		<inertial>
			<origin rpy = "0 0 0" xyz = "-0.080000 -1.110000 0.000000" />
			<mass value = "3.000000" />
			<inertia ixx = "0.1" ixy = "0" ixz = "0" iyy = "0.1" iyz = "0" izz = "0.1" />
		</inertial>
		<collision>
			<origin rpy = "-1.570796 0 0" xyz = "-0.080000 -1.110000 0.000000" />
			<geometry>
				<capsule length="0.12" radius="0.06"/>
			</geometry>
		</collision>
	</link>
	<joint name="ring_dist" type="revolute" >
		<parent link="ring_inter" />
		<child link="ring_dist" />
		<limit effort="1000.0" lower="-3.14" upper="0." velocity="0.5"/>
		<origin rpy = "0 0 0" xyz = "0.000000 0.00 0.000000" />
		<axis xyz = "0.000000 0.000000 1.000000" />
	</joint>
	<!-- PINKIE -->
	<link name="pinkie_prox" >
		<inertial>
            <origin rpy = "0 0 0" xyz = "-0.160000 -0.510000 0.000000" />
			<mass value = "4.500000" />
			<inertia ixx = "0.1" ixy = "0" ixz = "0" iyy = "0.1" iyz = "0" izz = "0.1" />
		</inertial>
		<collision>
			<origin rpy = "-1.570796 0 0" xyz = "-0.160000 -0.51000 0.000000" />
			<geometry>
				<capsule length="0.120" radius="0.06" />
			</geometry>
		</collision>
	</link>
	<joint name="pinkie_prox" type="spherical" >
		<parent link="palm" />
		<child link="pinkie_prox" />
		<origin rpy = "0 0 0" xyz = "-0.160000 -0.36000 0.0" />
	</joint>
	<link name="pinkie_inter" >
		<inertial>
			<origin rpy = "0 0 0" xyz = "-0.160000 -0.810000 0.000000" />
			<mass value = "3.000000" />
			<inertia ixx = "0.1" ixy = "0" ixz = "0" iyy = "0.1" iyz = "0" izz = "0.1" />
		</inertial>
		<collision>
			<origin rpy = "-1.570796 0 0" xyz = "-0.160000 -0.810000 0.000000" />
			<geometry>
				<capsule length="0.12" radius="0.06"/>
			</geometry>
		</collision>
	</link>
	<joint name="pinkie_inter" type="revolute" >
		<parent link="pinkie_prox" />
		<child link="pinkie_inter" />
		<limit effort="1000.0" lower="-3.14" upper="0." velocity="0.5"/>
		<origin rpy = "0 0 0" xyz = "0.000000 0.00 0.000000" />
		<axis xyz = "0.000000 0.000000 1.000000" />
	</joint>
	<link name="pinkie_dist" >
		<inertial>
			<origin rpy = "0 0 0" xyz = "-0.160000 -1.110000 0.000000" />
			<mass value = "3.000000" />
			<inertia ixx = "0.1" ixy = "0" ixz = "0" iyy = "0.1" iyz = "0" izz = "0.1" />
		</inertial>
		<collision>
			<origin rpy = "-1.570796 0 0" xyz = "-0.160000 -1.110000 0.000000" />
			<geometry>
				<capsule length="0.12" radius="0.06"/>
			</geometry>
		</collision>
	</link>
	<joint name="pinkie_dist" type="revolute" >
		<parent link="pinkie_inter" />
		<child link="pinkie_dist" />
		<limit effort="1000.0" lower="-3.14" upper="0." velocity="0.5"/>
		<origin rpy = "0 0 0" xyz = "0.000000 0.00 0.000000" />
		<axis xyz = "0.000000 0.000000 1.000000" />
	</joint>
</robot>
