<robot name="dumpUrdf">
	<link name="base" >
		<inertial>
			<origin rpy = "0 0 0" xyz = "0 0 0" />
			<mass value = "0.0001" />
			<inertia ixx = "0.0001" ixy = "0" ixz = "0" iyy = "0.0001" iyz = "0" izz = "0.0001" />
		</inertial>
	</link>
	<!-- wrist -->
	<link name="wrist" >
		<inertial>
            <origin rpy = "0 0.00000000 0.00000000" xyz = "0 0 0" />
			<mass value = "0.1" />
			<inertia ixx = "0.1" ixy = "0" ixz = "0" iyy = "0.1" iyz = "0" izz = "0.1" />
		</inertial>
		<collision>
            <origin rpy = "0 0.00000000 0.00000000" xyz = "0 0 0" />
			<geometry>
				<box size="0.05 0.05 0.2" />
			</geometry>
		</collision>
	</link>
	<joint name="wrist" type="fixed" >
		<parent link = "base" />
		<child link="wrist" />
        <origin rpy = "3.14 -1.57 0" xyz = "-2 0 0" />
	</joint>
	<!-- thumb -->
	<link name="pre_thumb" >
		<inertial>
            <origin rpy = "0 0 0" xyz = "0 0 0" />
			<mass value = "0.05" />
			<inertia ixx = "0.1" ixy = "0" ixz = "0" iyy = "0.1" iyz = "0" izz = "0.1" />
		</inertial>
		<collision>
			<origin rpy = "0 0 0" xyz = "0 0 0" />
			<geometry>
				<box size="0.05 0.05 0.2" />
			</geometry>
		</collision>
	</link>
	<joint name="pre_thumb" type="fixed" >
		<parent link="wrist" />
		<child link="pre_thumb" />
    	<origin rpy="0 0 0" xyz="0.14371320605278015 0.13853967189788818 0.18844783306121826"/>
	</joint>
	<link name="thumb_prox" >
		<inertial>
            <origin rpy = "0 0 0" xyz = "0 0 0" />
			<mass value = "0.05" />
			<inertia ixx = "0.1" ixy = "0" ixz = "0" iyy = "0.1" iyz = "0" izz = "0.1" />
		</inertial>
		<collision>
			<origin rpy = "0 0 0" xyz = "0 0 0" />
			<geometry>
				<box size="0.05 0.05 0.2" />
			</geometry>
		</collision>
	</link>
	<joint name="thumb_prox" type="revolute" >
		<parent link="pre_thumb" />
		<child link="thumb_prox" />
		<origin rpy = "0 0 0" xyz = "0.25435328483581543 0.16699939966201782 0.31131690740585327" />
		<axis xyz="0.00000000 0.00000000 1.00000000"/>
    	<limit effort="1000" lower="-3.14" upper="3.14" velocity="0.5"/>
	</joint>
	<link name="thumb_inter" >
		<inertial>
            <origin rpy = "0 0 0" xyz = "0 0 0" />
			<mass value = "0.05" />
			<inertia ixx = "0.1" ixy = "0" ixz = "0" iyy = "0.1" iyz = "0" izz = "0.1" />
		</inertial>
		<collision>
			<origin rpy = "0 0 0" xyz = "0 0 0" />
			<geometry>
				<box size="0.05 0.05 0.2" />
			</geometry>
		</collision>
	</link>
	<joint name="thumb_inter" type="revolute" >
		<parent link="thumb_prox" />
		<child link="thumb_inter" />
		<limit effort="1000.0" lower="-3.14" upper="3.14" velocity="0.5"/>
		<origin rpy = "0 0 0" xyz = "0.3422205150127411 0.18413037061691284 0.42374905943870544" />
		<axis xyz = "0.000000 1.000000 0.000000" />
	</joint>
	<link name="thumb_dist" >
		<inertial>
            <origin rpy = "0 0 0" xyz = "0 0 0" />
			<mass value = "0.05" />
			<inertia ixx = "0.1" ixy = "0" ixz = "0" iyy = "0.1" iyz = "0" izz = "0.1" />
		</inertial>
		<collision>
			<origin rpy = "0 0 0" xyz = "0 0 0" />
			<geometry>
				<box size="0.05 0.05 0.2" />
			</geometry>
		</collision>
	</link>
	<joint name="thumb_dist" type="revolute" >
		<parent link="thumb_inter" />
		<child link="thumb_dist" />
		<limit effort="1000.0" lower="-3.14" upper="3.14" velocity="0.5"/>
		<origin rpy = "0 0 0" xyz = "0.44784292578697205 0.17878860235214233 0.5556486248970032" />
		<axis xyz = "0.000000 1.000000 0.000000" />
	</joint>
	<!-- index -->
	<link name="pre_index" >
		<inertial>
            <origin rpy = "0 0 0" xyz = "0 0 0" />
			<mass value = "0.05" />
			<inertia ixx = "0.1" ixy = "0" ixz = "0" iyy = "0.1" iyz = "0" izz = "0.1" />
		</inertial>
		<collision>
			<origin rpy = "0 0 0" xyz = "0 0 0" />
			<geometry>
				<box size="0.05 0.05 0.2" />
			</geometry>
		</collision>
	</link>
	<joint name="pre_index" type="fixed" >
		<parent link="wrist" />
		<child link="pre_index" />
    	<origin rpy="0 0 0" xyz="0.0932370126247406 0.13456106185913086 0.523402988910675"/>
	</joint>
	<link name="index_prox" >
		<inertial>
            <origin rpy = "0 0 0" xyz = "0 0 0" />
			<mass value = "0.05" />
			<inertia ixx = "0.1" ixy = "0" ixz = "0" iyy = "0.1" iyz = "0" izz = "0.1" />
		</inertial>
		<collision>
			<origin rpy = "0 0 0" xyz = "0 0 0" />
			<geometry>
				<box size="0.05 0.05 0.2" />
			</geometry>
		</collision>
	</link>
	<joint name="index_prox" type="revolute" >
		<parent link="pre_index" />
		<child link="index_prox" />
		<origin rpy = "0 0 0" xyz = "0.0691772997379303 0.16612380743026733 0.6951615214347839" />
		<axis xyz="0.00000000 0.00000000 1.00000000"/>
    	<limit effort="1000" lower="-3.14" upper="3.14" velocity="0.5"/>
	</joint>
	<link name="index_inter" >
		<inertial>
            <origin rpy = "0 0 0" xyz = "0 0 0" />
			<mass value = "0.05" />
			<inertia ixx = "0.1" ixy = "0" ixz = "0" iyy = "0.1" iyz = "0" izz = "0.1" />
		</inertial>
		<collision>
			<origin rpy = "0 0 0" xyz = "0 0 0" />
			<geometry>
				<box size="0.05 0.05 0.2" />
			</geometry>
		</collision>
	</link>
	<joint name="index_inter" type="revolute" >
		<parent link="index_prox" />
		<child link="index_inter" />
		<limit effort="1000.0" lower="-3.14" upper="3.14" velocity="0.5"/>
		<origin rpy = "0 0 0" xyz = "0.06789520382881165 0.19676893949508667 0.8153725862503052" />
		<axis xyz = "0.000000 1.000000 0.000000" />
	</joint>
	<link name="index_dist" >
		<inertial>
            <origin rpy = "0 0 0" xyz = "0 0 0" />
			<mass value = "0.05" />
			<inertia ixx = "0.1" ixy = "0" ixz = "0" iyy = "0.1" iyz = "0" izz = "0.1" />
		</inertial>
		<collision>
			<origin rpy = "0 0 0" xyz = "0 0 0" />
			<geometry>
				<box size="0.05 0.05 0.2" />
			</geometry>
		</collision>
	</link>
	<joint name="index_dist" type="revolute" >
		<parent link="index_inter" />
		<child link="index_dist" />
		<limit effort="1000.0" lower="-3.14" upper="3.14" velocity="0.5"/>
		<origin rpy = "0 0 0" xyz = "0.067070871591568 0.22477388381958008 0.9387664198875427" />
		<axis xyz = "0.000000 1.000000 0.000000" />
	</joint>
	<!-- middle -->
	<link name="pre_middle" >
		<inertial>
            <origin rpy = "0 0 0" xyz = "0 0 0" />
			<mass value = "0.05" />
			<inertia ixx = "0.1" ixy = "0" ixz = "0" iyy = "0.1" iyz = "0" izz = "0.1" />
		</inertial>
		<collision>
			<origin rpy = "0 0 0" xyz = "0 0 0" />
			<geometry>
				<box size="0.05 0.05 0.2" />
			</geometry>
		</collision>
	</link>
	<joint name="pre_middle" type="fixed" >
		<parent link="wrist" />
		<child link="pre_middle" />
    	<origin rpy="0 0 0" xyz="-0.03998696804046631 0.1321360468864441 0.5598184466362"/>
	</joint>
	<link name="middle_prox" >
		<inertial>
            <origin rpy = "0 0 0" xyz = "0 0 0" />
			<mass value = "0.05" />
			<inertia ixx = "0.1" ixy = "0" ixz = "0" iyy = "0.1" iyz = "0" izz = "0.1" />
		</inertial>
		<collision>
			<origin rpy = "0 0 0" xyz = "0 0 0" />
			<geometry>
				<box size="0.05 0.05 0.2" />
			</geometry>
		</collision>
	</link>
	<joint name="middle_prox" type="revolute" >
		<parent link="pre_middle" />
		<child link="middle_prox" />
		<origin rpy = "0 0 0" xyz = "-0.08907824754714966 0.19644707441329956 0.7083621025085449" />
		<axis xyz="0.00000000 0.00000000 1.00000000"/>
    	<limit effort="1000" lower="-3.14" upper="3.14" velocity="0.5"/>
	</joint>
	<link name="middle_inter" >
		<inertial>
            <origin rpy = "0 0 0" xyz = "0 0 0" />
			<mass value = "0.05" />
			<inertia ixx = "0.1" ixy = "0" ixz = "0" iyy = "0.1" iyz = "0" izz = "0.1" />
		</inertial>
		<collision>
			<origin rpy = "0 0 0" xyz = "0 0 0" />
			<geometry>
				<box size="0.05 0.05 0.2" />
			</geometry>
		</collision>
	</link>
	<joint name="middle_inter" type="revolute" >
		<parent link="middle_prox" />
		<child link="middle_inter" />
		<limit effort="1000.0" lower="-3.14" upper="3.14" velocity="0.5"/>
		<origin rpy = "0 0 0" xyz = "-0.1132020354270935 0.23894309997558594 0.8295055627822876" />
		<axis xyz = "0.000000 1.000000 0.000000" />
	</joint>
	<link name="middle_dist" >
		<inertial>
            <origin rpy = "0 0 0" xyz = "0 0 0" />
			<mass value = "0.05" />
			<inertia ixx = "0.1" ixy = "0" ixz = "0" iyy = "0.1" iyz = "0" izz = "0.1" />
		</inertial>
		<collision>
			<origin rpy = "0 0 0" xyz = "0 0 0" />
			<geometry>
				<box size="0.05 0.05 0.2" />
			</geometry>
		</collision>
	</link>
	<joint name="middle_dist" type="revolute" >
		<parent link="middle_inter" />
		<child link="middle_dist" />
		<limit effort="1000.0" lower="-3.14" upper="3.14" velocity="0.5"/>
		<origin rpy = "0 0 0" xyz = "-0.13410881161689758 0.2635893225669861 0.9531867504119873" />
		<axis xyz = "0.000000 1.000000 0.000000" />
	</joint>
	<!-- ring -->
	<link name="pre_ring" >
		<inertial>
            <origin rpy = "0 0 0" xyz = "0 0 0" />
			<mass value = "0.05" />
			<inertia ixx = "0.1" ixy = "0" ixz = "0" iyy = "0.1" iyz = "0" izz = "0.1" />
		</inertial>
		<collision>
			<origin rpy = "0 0 0" xyz = "0 0 0" />
			<geometry>
				<box size="0.05 0.05 0.2" />
			</geometry>
		</collision>
	</link>
	<joint name="pre_ring" type="fixed" >
		<parent link="wrist" />
		<child link="pre_ring" />
    	<origin rpy="0 0 0" xyz="-0.16890421509742737 0.14315903186798096 0.48676130175590515"/>
	</joint>
	<link name="ring_prox" >
		<inertial>
            <origin rpy = "0 0 0" xyz = "0 0 0" />
			<mass value = "0.05" />
			<inertia ixx = "0.1" ixy = "0" ixz = "0" iyy = "0.1" iyz = "0" izz = "0.1" />
		</inertial>
		<collision>
			<origin rpy = "0 0 0" xyz = "0 0 0" />
			<geometry>
				<box size="0.05 0.05 0.2" />
			</geometry>
		</collision>
	</link>
	<joint name="ring_prox" type="revolute" >
		<parent link="pre_ring" />
		<child link="ring_prox" />
		<origin rpy = "0 0 0" xyz = "-0.20733147859573364 0.18892675638198853 0.6320534348487854" />
		<axis xyz="0.00000000 0.00000000 1.00000000"/>
    	<limit effort="1000" lower="-3.14" upper="3.14" velocity="0.5"/>
	</joint>
	<link name="ring_inter" >
		<inertial>
            <origin rpy = "0 0 0" xyz = "0 0 0" />
			<mass value = "0.05" />
			<inertia ixx = "0.1" ixy = "0" ixz = "0" iyy = "0.1" iyz = "0" izz = "0.1" />
		</inertial>
		<collision>
			<origin rpy = "0 0 0" xyz = "0 0 0" />
			<geometry>
				<box size="0.05 0.05 0.2" />
			</geometry>
		</collision>
	</link>
	<joint name="ring_inter" type="revolute" >
		<parent link="ring_prox" />
		<child link="ring_inter" />
		<limit effort="1000.0" lower="-3.14" upper="3.14" velocity="0.5"/>
		<origin rpy = "0 0 0" xyz = "-0.2510714530944824 0.22440940141677856 0.7506177425384521" />
		<axis xyz = "0.000000 1.000000 0.000000" />
	</joint>
	<link name="ring_dist" >
		<inertial>
            <origin rpy = "0 0 0" xyz = "0 0 0" />
			<mass value = "0.05" />
			<inertia ixx = "0.1" ixy = "0" ixz = "0" iyy = "0.1" iyz = "0" izz = "0.1" />
		</inertial>
		<collision>
			<origin rpy = "0 0 0" xyz = "0 0 0" />
			<geometry>
				<box size="0.05 0.05 0.2" />
			</geometry>
		</collision>
	</link>
	<joint name="ring_dist" type="revolute" >
		<parent link="ring_inter" />
		<child link="ring_dist" />
		<limit effort="1000.0" lower="-3.14" upper="3.14" velocity="0.5"/>
		<origin rpy = "0 0 0" xyz = "-0.28506338596343994 0.22448807954788208 0.8543031811714172" />
		<axis xyz = "0.000000 1.000000 0.000000" />
	</joint>
	<!-- pinkie -->
	<link name="pre_pinkie" >
		<inertial>
            <origin rpy = "0 0 0" xyz = "0 0 0" />
			<mass value = "0.05" />
			<inertia ixx = "0.1" ixy = "0" ixz = "0" iyy = "0.1" iyz = "0" izz = "0.1" />
		</inertial>
		<collision>
			<origin rpy = "0 0 0" xyz = "0 0 0" />
			<geometry>
				<box size="0.05 0.05 0.2" />
			</geometry>
		</collision>
	</link>
	<joint name="pre_pinkie" type="fixed" >
		<parent link="wrist" />
		<child link="pre_pinkie" />
    	<origin rpy="0 0 0" xyz="-0.25741010904312134 0.1655551791191101 0.40573370456695557"/>
	</joint>
	<link name="pinkie_prox" >
		<inertial>
            <origin rpy = "0 0 0" xyz = "0 0 0" />
			<mass value = "0.05" />
			<inertia ixx = "0.1" ixy = "0" ixz = "0" iyy = "0.1" iyz = "0" izz = "0.1" />
		</inertial>
		<collision>
			<origin rpy = "0 0 0" xyz = "0 0 0" />
			<geometry>
				<box size="0.05 0.05 0.2" />
			</geometry>
		</collision>
	</link>
	<joint name="pinkie_prox" type="revolute" >
		<parent link="pre_pinkie" />
		<child link="pinkie_prox" />
		<origin rpy = "0 0 0" xyz = "-0.30925989151000977 0.1727619767189026 0.501175045967102" />
		<axis xyz="0.00000000 0.00000000 1.00000000"/>
    	<limit effort="1000" lower="-3.14" upper="3.14" velocity="0.5"/>
	</joint>
	<link name="pinkie_inter" >
		<inertial>
            <origin rpy = "0 0 0" xyz = "0 0 0" />
			<mass value = "0.05" />
			<inertia ixx = "0.1" ixy = "0" ixz = "0" iyy = "0.1" iyz = "0" izz = "0.1" />
		</inertial>
		<collision>
			<origin rpy = "0 0 0" xyz = "0 0 0" />
			<geometry>
				<box size="0.05 0.05 0.2" />
			</geometry>
		</collision>
	</link>
	<joint name="pinkie_inter" type="revolute" >
		<parent link="pinkie_prox" />
		<child link="pinkie_inter" />
		<limit effort="1000.0" lower="-3.14" upper="3.14" velocity="0.5"/>
		<origin rpy = "0 0 0" xyz = "-0.36576420068740845 0.1841568946838379 0.5903811454772949" />
		<axis xyz = "0.000000 1.000000 0.000000" />
	</joint>
	<link name="pinkie_dist" >
		<inertial>
            <origin rpy = "0 0 0" xyz = "0 0 0" />
			<mass value = "0.05" />
			<inertia ixx = "0.1" ixy = "0" ixz = "0" iyy = "0.1" iyz = "0" izz = "0.1" />
		</inertial>
		<collision>
			<origin rpy = "0 0 0" xyz = "0 0 0" />
			<geometry>
				<box size="0.05 0.05 0.2" />
			</geometry>
		</collision>
	</link>
	<joint name="pinkie_dist" type="revolute" >
		<parent link="pinkie_inter" />
		<child link="pinkie_dist" />
		<limit effort="1000.0" lower="-3.14" upper="3.14" velocity="0.5"/>
		<origin rpy = "0 0 0" xyz = "-0.40665045380592346 0.19041121006011963 0.6771543025970459" />
		<axis xyz = "0.000000 1.000000 0.000000" />
	</joint>
</robot>
