<robot name="dumpUrdf">
	<link name="base" >
		<inertial>
			<origin rpy = "0 0 0" xyz = "0 0 0" />
			<mass value = "0.0001" />
			<inertia ixx = "0.0001" ixy = "0" ixz = "0" iyy = "0.0001" iyz = "0" izz = "0.0001" />
		</inertial>
	</link>
	<link name="root" >
		<inertial>
			<origin rpy = "0 0 0" xyz = "0.000000 0.280000 0.000000" />
			<mass value = "6.000000" />
			<inertia ixx = "0.1" ixy = "0" ixz = "0" iyy = "0.1" iyz = "0" izz = "0.1" />
		</inertial>
		<collision>
				<origin rpy = "0 0 0" xyz = "0.000000 0.280000 0.000000" />
			<geometry>
				<sphere radius = "0.360000" />
			</geometry>
		</collision>
	</link>
	<joint name="root" type="fixed" >
		<parent link = "base" />
		<child link="root" />
				<origin rpy = "0 0 0" xyz = "0.000000 0.000000 0.000000" />
	</joint>
	<link name="chest" >
		<inertial>
            <origin rpy = "0 0 0" xyz = "0.000000 0.480000 0.000000" />
			<mass value = "14.000000" />
			<inertia ixx = "0.1" ixy = "0" ixz = "0" iyy = "0.1" iyz = "0" izz = "0.1" />
		</inertial>
		<collision>
				<origin rpy = "0 0 0" xyz = "0.000000 0.480000 0.000000" />
			<geometry>
				<sphere radius = "0.440000" />
			</geometry>
		</collision>
	</link>
	<joint name="chest" type="spherical" >
		<parent link="root" />
		<child link="chest" />
				<origin rpy = "0 0 0" xyz = "0.000000 0.944604 0.000000" />
	</joint>
	<link name="neck" >
		<inertial>
				<origin rpy = "0 0 0" xyz = "0.000000 0.700000 0.000000" />
			 <mass value = "2.000000" />
			<inertia ixx = "0.1" ixy = "0" ixz = "0" iyy = "0.1" iyz = "0" izz = "0.1" />
		</inertial>
		<collision>
				<origin rpy = "0 0 0" xyz = "0.000000 0.700000 0.000000" />
			<geometry>
				<sphere radius = "0.410000" />
			</geometry>
		</collision>
	</link>
	<joint name="neck" type="spherical" >
		<parent link="chest" />
		<child link="neck" />
				<origin rpy = "0 0 0" xyz = "0.000000 0.895576 0.000000" />
	</joint>
	<link name="right_hip" >
		<inertial>
				<origin rpy = "0 0 0" xyz = "0.000000 -0.840000 0.000000" />
			 <mass value = "4.500000" />
			<inertia ixx = "0.1" ixy = "0" ixz = "0" iyy = "0.1" iyz = "0" izz = "0.1" />
		</inertial>
		<collision>
				<origin rpy = "-1.570796 0 0" xyz = "0.000000 -0.840000 0.000000" />
			<geometry>
				<capsule length="1.200000" radius="0.220000"/>
			</geometry>
		</collision>
	</link>
	<joint name="right_hip" type="fixed" >
		<parent link="root" />
		<child link="right_hip" />
				<origin rpy = "0 0 0" xyz = "0.000000 0.000000 0.339548" />
	</joint>
	<link name="right_knee" >
		<inertial>
				<origin rpy = "0 0 0" xyz = "0.000000 -0.800000 0.000000" />
			 <mass value = "3.000000" />
			<inertia ixx = "0.1" ixy = "0" ixz = "0" iyy = "0.1" iyz = "0" izz = "0.1" />
		</inertial>
		<collision>
				<origin rpy = "-1.570796 0 0" xyz = "0.000000 -0.800000 0.000000" />
			<geometry>
				<capsule length="1.240000" radius="0.200000"/>
			</geometry>
		</collision>
	</link>
	<joint name="right_knee" type="fixed" >
		<parent link="right_hip" />
		<child link="right_knee" />
		 <limit effort="1000.0" lower="-3.14" upper="0." velocity="0.5"/>
			<origin rpy = "0 0 0" xyz = "0.000000 -1.686184 0.000000" />
		<axis xyz = "0.000000 0.000000 1.000000" />
	</joint>
	<link name="right_ankle" >
		<inertial>
				<origin rpy = "0 0 0" xyz = "0.180000 -0.090000 0.000000" />
			 <mass value = "100.000000" />
			<inertia ixx = "0.1" ixy = "0" ixz = "0" iyy = "0.1" iyz = "0" izz = "0.1" />
		</inertial>
		<collision>
				<origin rpy = "0 0 0" xyz = "0.180000 -0.090000 0.000000" />
			<geometry>
				<box size="0.708000 0.220000 0.360000" />
			</geometry>
		</collision>
	</link>
	<joint name="right_ankle" type="fixed" >
		<parent link="right_knee" />
		<child link="right_ankle" />
				<origin rpy = "0 0 0" xyz = "0.000000 -1.639480 0.000000" />
	</joint>
	<link name="right_shoulder" >
		<inertial>
				<origin rpy = "0 0 0" xyz = "0.000000 -0.560000 0.000000" />
			 <mass value = "1.500000" />
			<inertia ixx = "0.1" ixy = "0" ixz = "0" iyy = "0.1" iyz = "0" izz = "0.1" />
		</inertial>
		<collision>
				<origin rpy = "-1.570796 0 0" xyz = "0.000000 -0.560000 0.000000" />
			<geometry>
				<capsule length="0.720000" radius="0.180000"/>
			</geometry>
		</collision>
	</link>
	<joint name="right_shoulder" type="spherical" >
		<parent link="chest" />
		<child link="right_shoulder" />
				<origin rpy = "0 0 0" xyz = "-0.096200 0.974000 0.732440" />
	</joint>
	<link name="right_elbow" >
		<inertial>
				<origin rpy = "0 0 0" xyz = "0.000000 -0.480000 0.000000" />
			 <mass value = "1.000000" />
			<inertia ixx = "0.1" ixy = "0" ixz = "0" iyy = "0.1" iyz = "0" izz = "0.1" />
		</inertial>
		<collision>
				<origin rpy = "-1.570796 0 0" xyz = "0.000000 -0.480000 0.000000" />
			<geometry>
				<capsule length="0.540000" radius="0.160000"/>
			</geometry>
		</collision>
	</link>
	<joint name="right_elbow" type="revolute" >
		<parent link="right_shoulder" />
		<child link="right_elbow" />
		<limit effort="1000.0" lower="0" upper="3.14" velocity="0.5"/>
				<origin rpy = "0 0 0" xyz = "0.000000 -1.099152 0.000000" />
		<axis xyz = "0.000000 0.000000 1.000000" />
	</joint>
	<link name="right_wrist" >
		<inertial>
				<origin rpy = "0 0 0" xyz = "0.000000 0.000000 0.000000" />
			 <mass value = "0.500000" />
			<inertia ixx = "0.1" ixy = "0" ixz = "0" iyy = "0.1" iyz = "0" izz = "0.1" />
		</inertial>
		<collision>
				<origin rpy = "0 0 0" xyz = "0.000000 0.000000 0.000000" />
			<geometry>
				<sphere radius = "0.160000" />
			</geometry>
		</collision>
	</link>
	<joint name="right_wrist" type="spherical" >
		<parent link="right_elbow" />
		<child link="right_wrist" />
		<origin rpy = "1.57 0 0" xyz = "0.000000 -1.035788 0.000000" />
	</joint>
	<link name="thumb_prox" >
		<inertial>
            <origin rpy = "0 0 0" xyz = "0 0 0.04" />
			<mass value = "0.05" />
			<inertia ixx = "0.1" ixy = "0" ixz = "0" iyy = "0.1" iyz = "0" izz = "0.1" />
		</inertial>
		<collision>
			<origin rpy = "0 0 0" xyz = "0 0 0.04" />
			<geometry>
				<box size="0.05 0.05 0.08" />
			</geometry>
		</collision>
	</link>
	<joint name="thumb_prox" type="revolute" >
		<parent link="right_wrist" />
		<child link="thumb_prox" />
		<origin rpy = "3.14 -2.81 0" xyz = "0.25435328483581543 0 0" />
		<axis xyz = "0.000000 1.000000 0.000000" />
    	<limit effort="1000" lower="0" upper="2" velocity="0.5"/>
	</joint>
	<link name="thumb_inter" >
		<inertial>
            <origin rpy = "0 0 0" xyz = "0 0 0.04" />
			<mass value = "0.05" />
			<inertia ixx = "0.1" ixy = "0" ixz = "0" iyy = "0.1" iyz = "0" izz = "0.1" />
		</inertial>
		<collision>
			<origin rpy = "0 0 0" xyz = "0 0 0.04" />
			<geometry>
				<box size="0.05 0.05 0.08" />
			</geometry>
		</collision>
	</link>
	<joint name="thumb_inter" type="revolute" >
		<parent link="thumb_prox" />
		<child link="thumb_inter" />
		<limit effort="1000.0" lower="0" upper="2" velocity="0.5"/>
		<origin rpy = "0 0 0" xyz = "0 0 0.11243215203285217" />
		<axis xyz = "0.000000 1.000000 0.000000" />
	</joint>
	<link name="thumb_dist" >
		<inertial>
            <origin rpy = "0 0 0" xyz = "0 0 0.04" />
			<mass value = "0.05" />
			<inertia ixx = "0.1" ixy = "0" ixz = "0" iyy = "0.1" iyz = "0" izz = "0.1" />
		</inertial>
		<collision>
			<origin rpy = "0 0 0" xyz = "0 0 0.04" />
			<geometry>
				<box size="0.05 0.05 0.08" />
			</geometry>
		</collision>
	</link>
	<joint name="thumb_dist" type="revolute" >
		<parent link="thumb_inter" />
		<child link="thumb_dist" />
		<limit effort="1000.0" lower="0" upper="2" velocity="0.5"/>
		<origin rpy = "0 0 0" xyz = "0 0 0.13189956545829773" />
		<axis xyz = "0.000000 1.000000 0.000000" />
	</joint>
	<!-- index -->
	<link name="index_prox" >
		<inertial>
            <origin rpy = "0 0 0" xyz = "0 0 0.04" />
			<mass value = "0.05" />
			<inertia ixx = "0.1" ixy = "0" ixz = "0" iyy = "0.1" iyz = "0" izz = "0.1" />
		</inertial>
		<collision>
			<origin rpy = "0 0 0" xyz = "0 0 0.04" />
			<geometry>
				<box size="0.05 0.05 0.08" />
			</geometry>
		</collision>
	</link>
	<joint name="index_prox" type="revolute" >
		<parent link="right_wrist" />
		<child link="index_prox" />
		<origin rpy = "0 0 0" xyz = "0.0691772997379303 0 0" />
		<axis xyz = "1.000000 0.000000 0.000000" />
    	<limit effort="1000" lower="0" upper="2" velocity="0.5"/>
	</joint>
	<link name="index_inter" >
		<inertial>
            <origin rpy = "0 0 0" xyz = "0 0 0.04" />
			<mass value = "0.05" />
			<inertia ixx = "0.1" ixy = "0" ixz = "0" iyy = "0.1" iyz = "0" izz = "0.1" />
		</inertial>
		<collision>
			<origin rpy = "0 0 0" xyz = "0 0 0.04" />
			<geometry>
				<box size="0.05 0.05 0.08" />
			</geometry>
		</collision>
	</link>
	<joint name="index_inter" type="revolute" >
		<parent link="index_prox" />
		<child link="index_inter" />
		<limit effort="1000.0" lower="0" upper="2" velocity="0.5"/>
		<origin rpy = "0 0 0" xyz = "0 0 0.12021106481552124" />
		<axis xyz = "1.000000 0.000000 0.000000" />
	</joint>
	<link name="index_dist" >
		<inertial>
            <origin rpy = "0 0 0" xyz = "0 0 0.04" />
			<mass value = "0.05" />
			<inertia ixx = "0.1" ixy = "0" ixz = "0" iyy = "0.1" iyz = "0" izz = "0.1" />
		</inertial>
		<collision>
			<origin rpy = "0 0 0" xyz = "0 0 0.04" />
			<geometry>
				<box size="0.05 0.05 0.08" />
			</geometry>
		</collision>
	</link>
	<joint name="index_dist" type="revolute" >
		<parent link="index_inter" />
		<child link="index_dist" />
		<limit effort="1000.0" lower="0" upper="2" velocity="0.5"/>
		<origin rpy = "0 0 0" xyz = "0 0 0.12339383363723755" />
		<axis xyz = "1.000000 0.000000 0.000000" />
	</joint>
	<!-- middle -->
	<link name="middle_prox" >
		<inertial>
            <origin rpy = "0 0 0" xyz = "0 0 0.04" />
			<mass value = "0.05" />
			<inertia ixx = "0.1" ixy = "0" ixz = "0" iyy = "0.1" iyz = "0" izz = "0.1" />
		</inertial>
		<collision>
			<origin rpy = "0 0 0" xyz = "0 0 0.04" />
			<geometry>
				<box size="0.05 0.05 0.08" />
			</geometry>
		</collision>
	</link>
	<joint name="middle_prox" type="revolute" >
		<parent link="right_wrist" />
		<child link="middle_prox" />
		<origin rpy = "0 0 0.1" xyz = "-0.08907824754714966 0 0" />
		<axis xyz = "1.000000 0.000000 0.000000" />
    	<limit effort="1000" lower="0" upper="2" velocity="0.5"/>
	</joint>
	<link name="middle_inter" >
		<inertial>
            <origin rpy = "0 0 0" xyz = "0 0 0.04" />
			<mass value = "0.05" />
			<inertia ixx = "0.1" ixy = "0" ixz = "0" iyy = "0.1" iyz = "0" izz = "0.1" />
		</inertial>
		<collision>
			<origin rpy = "0 0 0" xyz = "0 0 0.04" />
			<geometry>
				<box size="0.05 0.05 0.08" />
			</geometry>
		</collision>
	</link>
	<joint name="middle_inter" type="revolute" >
		<parent link="middle_prox" />
		<child link="middle_inter" />
		<limit effort="1000.0" lower="0" upper="2" velocity="0.5"/>
		<origin rpy = "0 0 0" xyz = "0 0 0.12114346027374268" />
		<axis xyz = "1.000000 0.000000 0.000000" />
	</joint>
	<link name="middle_dist" >
		<inertial>
            <origin rpy = "0 0 0" xyz = "0 0 0.04" />
			<mass value = "0.05" />
			<inertia ixx = "0.1" ixy = "0" ixz = "0" iyy = "0.1" iyz = "0" izz = "0.1" />
		</inertial>
		<collision>
			<origin rpy = "0 0 0" xyz = "0 0 0.04" />
			<geometry>
				<box size="0.05 0.05 0.08" />
			</geometry>
		</collision>
	</link>
	<joint name="middle_dist" type="revolute" >
		<parent link="middle_inter" />
		<child link="middle_dist" />
		<limit effort="1000.0" lower="0" upper="2" velocity="0.5"/>
		<origin rpy = "0 0 0" xyz = "0 0 0.12368118762969971" />
		<axis xyz = "1.000000 0.000000 0.000000" />
	</joint>
	<!-- ring -->
	<link name="ring_prox" >
		<inertial>
            <origin rpy = "0 0 0" xyz = "0 0 0.04" />
			<mass value = "0.05" />
			<inertia ixx = "0.1" ixy = "0" ixz = "0" iyy = "0.1" iyz = "0" izz = "0.1" />
		</inertial>
		<collision>
			<origin rpy = "0 0 0" xyz = "0 0 0.04" />
			<geometry>
				<box size="0.05 0.05 0.08" />
			</geometry>
		</collision>
	</link>
	<joint name="ring_prox" type="revolute" >
		<parent link="right_wrist" />
		<child link="ring_prox" />
		<origin rpy = "0 -0.05 0.11" xyz = "-0.20733147859573364 0 0" />
		<axis xyz = "1.000000 0.000000 0.000000" />
    	<limit effort="1000" lower="0" upper="2" velocity="0.5"/>
	</joint>
	<link name="ring_inter" >
		<inertial>
            <origin rpy = "0 0 0" xyz = "0 0 0.04" />
			<mass value = "0.05" />
			<inertia ixx = "0.1" ixy = "0" ixz = "0" iyy = "0.1" iyz = "0" izz = "0.1" />
		</inertial>
		<collision>
			<origin rpy = "0 0 0" xyz = "0 0 0.04" />
			<geometry>
				<box size="0.05 0.05 0.08" />
			</geometry>
		</collision>
	</link>
	<joint name="ring_inter" type="revolute" >
		<parent link="ring_prox" />
		<child link="ring_inter" />
		<limit effort="1000.0" lower="0" upper="2" velocity="0.5"/>
		<origin rpy = "0 0 0" xyz = "0 0 0.11856430768966675" />
		<axis xyz = "1.000000 0.000000 0.000000" />
	</joint>
	<link name="ring_dist" >
		<inertial>
            <origin rpy = "0 0 0" xyz = "0 0 0.04" />
			<mass value = "0.05" />
			<inertia ixx = "0.1" ixy = "0" ixz = "0" iyy = "0.1" iyz = "0" izz = "0.1" />
		</inertial>
		<collision>
			<origin rpy = "0 0 0" xyz = "0 0 0.04" />
			<geometry>
				<box size="0.05 0.05 0.08" />
			</geometry>
		</collision>
	</link>
	<joint name="ring_dist" type="revolute" >
		<parent link="ring_inter" />
		<child link="ring_dist" />
		<limit effort="1000.0" lower="0" upper="2" velocity="0.5"/>
		<origin rpy = "0 0 0" xyz = "0 0 0.10368543863296509" />
		<axis xyz = "1.000000 0.000000 0.000000" />
	</joint>
	<!-- pinkie -->
	<link name="pinkie_prox" >
		<inertial>
            <origin rpy = "0 0 0" xyz = "0 0 0.04" />
			<mass value = "0.05" />
			<inertia ixx = "0.1" ixy = "0" ixz = "0" iyy = "0.1" iyz = "0" izz = "0.1" />
		</inertial>
		<collision>
			<origin rpy = "0 0 0" xyz = "0 0 0.04" />
			<geometry>
				<box size="0.05 0.05 0.08" />
			</geometry>
		</collision>
	</link>
	<joint name="pinkie_prox" type="revolute" >
		<parent link="right_wrist" />
		<child link="pinkie_prox" />
		<origin rpy = "0 -0.13 0.21" xyz = "-0.30925989151000977 0 0" />
		<axis xyz = "1.000000 0.000000 0.000000" />
    	<limit effort="1000" lower="0" upper="2" velocity="0.5"/>
	</joint>
	<link name="pinkie_inter" >
		<inertial>
            <origin rpy = "0 0 0" xyz = "0 0 0.04" />
			<mass value = "0.05" />
			<inertia ixx = "0.1" ixy = "0" ixz = "0" iyy = "0.1" iyz = "0" izz = "0.1" />
		</inertial>
		<collision>
			<origin rpy = "0 0 0" xyz = "0 0 0.04" />
			<geometry>
				<box size="0.05 0.05 0.08" />
			</geometry>
		</collision>
	</link>
	<joint name="pinkie_inter" type="revolute" >
		<parent link="pinkie_prox" />
		<child link="pinkie_inter" />
		<limit effort="1000.0" lower="0" upper="2" velocity="0.5"/>
		<origin rpy = "0 0 0" xyz = "0 0 0.08920609951019287" />
		<axis xyz = "1.000000 0.000000 0.000000" />
	</joint>
	<link name="pinkie_dist" >
		<inertial>
            <origin rpy = "0 0 0" xyz = "0 0 0.04" />
			<mass value = "0.05" />
			<inertia ixx = "0.1" ixy = "0" ixz = "0" iyy = "0.1" iyz = "0" izz = "0.1" />
		</inertial>
		<collision>
			<origin rpy = "0 0 0" xyz = "0 0 0.04" />
			<geometry>
				<box size="0.05 0.05 0.08" />
			</geometry>
		</collision>
	</link>
	<joint name="pinkie_dist" type="revolute" >
		<parent link="pinkie_inter" />
		<child link="pinkie_dist" />
		<limit effort="1000.0" lower="0" upper="2" velocity="0.5"/>
		<origin rpy = "0 0 0" xyz = "0 0 0.08677315711975098" />
		<axis xyz = "1.000000 0.000000 0.000000" />
	</joint>
	<link name="left_hip" >
		<inertial>
				<origin rpy = "0 0 0" xyz = "0.000000 -0.840000 0.000000" />
			 <mass value = "4.500000" />
			<inertia ixx = "0.1" ixy = "0" ixz = "0" iyy = "0.1" iyz = "0" izz = "0.1" />
		</inertial>
		<collision>
				<origin rpy = "-1.570796 0 0" xyz = "0.000000 -0.840000 0.000000" />
			<geometry>
				<capsule length="1.200000" radius="0.220000"/>
			</geometry>
		</collision>
	</link>
	<joint name="left_hip" type="fixed" >
		<parent link="root" />
		<child link="left_hip" />
				<origin rpy = "0 0 0" xyz = "0.000000 0.000000 -0.339548" />
	</joint>
	<link name="left_knee" >
		<inertial>
				<origin rpy = "0 0 0" xyz = "0.000000 -0.800000 0.000000" />
			 <mass value = "3.000000" />
			<inertia ixx = "0.1" ixy = "0" ixz = "0" iyy = "0.1" iyz = "0" izz = "0.1" />
		</inertial>
		<collision>
				<origin rpy = "-1.570796 0 0" xyz = "0.000000 -0.800000 0.000000" />
			<geometry>
				<capsule length="1.240000" radius="0.200000"/>
			</geometry>
		</collision>
	</link>
	<joint name="left_knee" type="fixed" >
		<parent link="left_hip" />
		<child link="left_knee" />
		<limit effort="1000.0" lower="-3.14" upper="0." velocity="0.5"/>
				<origin rpy = "0 0 0" xyz = "0.000000 -1.686184 0.000000" />
		<axis xyz = "0.000000 0.000000 1.000000" />
	</joint>
	<link name="left_ankle" >
		<inertial>
				<origin rpy = "0 0 0" xyz = "0.180000 -0.090000 0.000000" />
			 <mass value = "100.000000" />
			<inertia ixx = "0.1" ixy = "0" ixz = "0" iyy = "0.1" iyz = "0" izz = "0.1" />
		</inertial>
		<collision>
				<origin rpy = "0 0 0" xyz = "0.180000 -0.090000 0.000000" />
			<geometry>
				<box size="0.708000 0.220000 0.360000" />
			</geometry>
		</collision>
	</link>
	<joint name="left_ankle" type="fixed" >
		<parent link="left_knee" />
		<child link="left_ankle" />
				<origin rpy = "0 0 0" xyz = "0.000000 -1.639480 0.000000" />
	</joint>
	<link name="left_shoulder" >
		<inertial>
				<origin rpy = "0 0 0" xyz = "0.000000 -0.560000 0.000000" />
			 <mass value = "1.500000" />
			<inertia ixx = "0.1" ixy = "0" ixz = "0" iyy = "0.1" iyz = "0" izz = "0.1" />
		</inertial>
		<collision>
				<origin rpy = "-1.570796 0 0" xyz = "0.000000 -0.560000 0.000000" />
			<geometry>
				<capsule length="0.720000" radius="0.180000"/>
			</geometry>
		</collision>
	</link>
	<joint name="left_shoulder" type="spherical" >
		<parent link="chest" />
		<child link="left_shoulder" />
				<origin rpy = "0 0 0" xyz = "-0.096200 0.974000 -0.732440" />
	</joint>
	<link name="left_elbow" >
		<inertial>
				<origin rpy = "0 0 0" xyz = "0.000000 -0.480000 0.000000" />
			 <mass value = "1.000000" />
			<inertia ixx = "0.1" ixy = "0" ixz = "0" iyy = "0.1" iyz = "0" izz = "0.1" />
		</inertial>
		<collision>
				<origin rpy = "-1.570796 0 0" xyz = "0.000000 -0.480000 0.000000" />
			<geometry>
				<capsule length="0.540000" radius="0.160000"/>
			</geometry>
		</collision>
	</link>
	<joint name="left_elbow" type="revolute" >
		<parent link="left_shoulder" />
		<child link="left_elbow" />
		<limit effort="1000.0" lower="0" upper="3.14" velocity="0.5"/>
				<origin rpy = "0 0 0" xyz = "0.000000 -1.099152 0.000000" />
		<axis xyz = "0.000000 0.000000 1.000000" />
	</joint>
	<link name="left_wrist" >
		<inertial>
				<origin rpy = "0 0 0" xyz = "0.000000 0.000000 0.000000" />
			 <mass value = "0.500000" />
			<inertia ixx = "0.1" ixy = "0" ixz = "0" iyy = "0.1" iyz = "0" izz = "0.1" />
		</inertial>
		<collision>
				<origin rpy = "0 0 0" xyz = "0.000000 0.000000 0.000000" />
			<geometry>
				<sphere radius = "0.160000" />
			</geometry>
		</collision>
	</link>
	<joint name="left_wrist" type="fixed" >
		<parent link="left_elbow" />
		<child link="left_wrist" />
				<origin rpy = "0 0 0" xyz = "0.000000 -1.035788 0.000000" />
	</joint>
</robot>
